2021-02-21 23:51:26: Falling back to TensorFlow client; we recommended you install the Cloud TPU client directly with pip install cloud-tpu-client.
2021-02-21 23:51:36: Starting new HTTPS connection (1): drive.google.com:443
2021-02-21 23:51:37: https://drive.google.com:443 "GET /uc?id=1CPSeum3HpopfomUEK1gybeuIVoeJT_Eo HTTP/1.1" 200 None
2021-02-21 23:51:37: Starting new HTTPS connection (1): docs.google.com:443
2021-02-21 23:51:37: https://docs.google.com:443 "GET /uc?export=download&confirm=UkOK&id=1CPSeum3HpopfomUEK1gybeuIVoeJT_Eo HTTP/1.1" 200 None
2021-02-21 23:51:38: https://docs.google.com:443 "GET /uc?export=download&confirm=iuZp&id=1CPSeum3HpopfomUEK1gybeuIVoeJT_Eo HTTP/1.1" 302 None
2021-02-21 23:51:38: Starting new HTTPS connection (1): doc-0o-ac-docs.googleusercontent.com:443
2021-02-21 23:51:38: https://doc-0o-ac-docs.googleusercontent.com:443 "GET /docs/securesc/gu54tol4tjdda6m9u1ato8svh32r835g/lpd597v9kocln7f08hks7d9rreh58l79/1613947875000/02091636547948030128/11666087542888184340Z/1CPSeum3HpopfomUEK1gybeuIVoeJT_Eo?e=download HTTP/1.1" 302 0
2021-02-21 23:51:38: https://docs.google.com:443 "GET /nonceSigner?nonce=obib78cl4s66o&continue=https://doc-0o-ac-docs.googleusercontent.com/docs/securesc/gu54tol4tjdda6m9u1ato8svh32r835g/lpd597v9kocln7f08hks7d9rreh58l79/1613947875000/02091636547948030128/11666087542888184340Z/1CPSeum3HpopfomUEK1gybeuIVoeJT_Eo?e%3Ddownload&hash=0um7ith3bd9a13kev07vkmdc15g2n2l7 HTTP/1.1" 302 0
2021-02-21 23:51:39: https://doc-0o-ac-docs.googleusercontent.com:443 "GET /docs/securesc/gu54tol4tjdda6m9u1ato8svh32r835g/lpd597v9kocln7f08hks7d9rreh58l79/1613947875000/02091636547948030128/11666087542888184340Z/1CPSeum3HpopfomUEK1gybeuIVoeJT_Eo?e=download&nonce=obib78cl4s66o&user=11666087542888184340Z&hash=ifmrv9dcfe3liqq12ht1brhq5a3lp47d HTTP/1.1" 200 None
2021-02-21 23:58:33: Starting new HTTPS connection (1): drive.google.com:443
2021-02-21 23:58:35: https://drive.google.com:443 "GET /uc?id=1971Xk5RwedbudGgTIrGAL4F7Aifu7id1 HTTP/1.1" 302 None
2021-02-21 23:58:35: Starting new HTTPS connection (1): doc-0s-ac-docs.googleusercontent.com:443
2021-02-21 23:58:35: https://doc-0s-ac-docs.googleusercontent.com:443 "GET /docs/securesc/gu54tol4tjdda6m9u1ato8svh32r835g/99c65eitg0ge03pnchq50qnqefvhqvrv/1613948250000/02091636547948030128/11666087542888184340Z/1971Xk5RwedbudGgTIrGAL4F7Aifu7id1 HTTP/1.1" 302 0
2021-02-21 23:58:35: Starting new HTTPS connection (1): docs.google.com:443
2021-02-21 23:58:36: https://docs.google.com:443 "GET /nonceSigner?nonce=0rmrlt5ljqq3i&continue=https://doc-0s-ac-docs.googleusercontent.com/docs/securesc/gu54tol4tjdda6m9u1ato8svh32r835g/99c65eitg0ge03pnchq50qnqefvhqvrv/1613948250000/02091636547948030128/11666087542888184340Z/1971Xk5RwedbudGgTIrGAL4F7Aifu7id1&hash=q2uuvlmgsqj162t4launpts13sthcbp3 HTTP/1.1" 302 0
2021-02-21 23:58:36: https://doc-0s-ac-docs.googleusercontent.com:443 "GET /docs/securesc/gu54tol4tjdda6m9u1ato8svh32r835g/99c65eitg0ge03pnchq50qnqefvhqvrv/1613948250000/02091636547948030128/11666087542888184340Z/1971Xk5RwedbudGgTIrGAL4F7Aifu7id1?nonce=0rmrlt5ljqq3i&user=11666087542888184340Z&hash=03hefn3ne0du29rlli60qlgpau35k90k HTTP/1.1" 200 None
2021-02-21 23:58:40: 5 out of the last 46 calls to <function Model.make_predict_function.<locals>.predict_function at 0x7ff27c24d280> triggered tf.function retracing. Tracing is expensive and the excessive number of tracings could be due to (1) creating @tf.function repeatedly in a loop, (2) passing tensors with different shapes, (3) passing Python objects instead of tensors. For (1), please define your @tf.function outside of the loop. For (2), @tf.function has experimental_relax_shapes=True option that relaxes argument shapes that can avoid unnecessary retracing. For (3), please refer to https://www.tensorflow.org/guide/function#controlling_retracing and https://www.tensorflow.org/api_docs/python/tf/function for  more details.
2021-02-22 00:00:07: 5 out of the last 46 calls to <function Model.make_predict_function.<locals>.predict_function at 0x7ff2b97254c0> triggered tf.function retracing. Tracing is expensive and the excessive number of tracings could be due to (1) creating @tf.function repeatedly in a loop, (2) passing tensors with different shapes, (3) passing Python objects instead of tensors. For (1), please define your @tf.function outside of the loop. For (2), @tf.function has experimental_relax_shapes=True option that relaxes argument shapes that can avoid unnecessary retracing. For (3), please refer to https://www.tensorflow.org/guide/function#controlling_retracing and https://www.tensorflow.org/api_docs/python/tf/function for  more details.
2021-02-22 00:00:25: 5 out of the last 16 calls to <function Model.make_predict_function.<locals>.predict_function at 0x7ff27c1efdc0> triggered tf.function retracing. Tracing is expensive and the excessive number of tracings could be due to (1) creating @tf.function repeatedly in a loop, (2) passing tensors with different shapes, (3) passing Python objects instead of tensors. For (1), please define your @tf.function outside of the loop. For (2), @tf.function has experimental_relax_shapes=True option that relaxes argument shapes that can avoid unnecessary retracing. For (3), please refer to https://www.tensorflow.org/guide/function#controlling_retracing and https://www.tensorflow.org/api_docs/python/tf/function for  more details.
2021-02-26 09:37:55: Starting new HTTPS connection (1): api.telegram.org:443
2021-02-26 09:37:55: https://api.telegram.org:443 "GET /bot1465974332:AAGqzVPLOfgUzKK3ZtEb9U9k8wb9srVk_LE/getMe HTTP/1.1" 200 206
2021-02-26 09:37:58: Making request: POST https://oauth2.googleapis.com/token
2021-02-26 09:37:58: Starting new HTTPS connection (1): oauth2.googleapis.com:443
2021-02-26 09:37:59: https://oauth2.googleapis.com:443 "POST /token HTTP/1.1" 400 None
2021-02-26 09:38:15: Generated new state IUzN88ia4QrYAgxQ6oXZ9mpGRdflpF.
2021-02-26 09:38:28: "GET /?error=access_denied&state=IUzN88ia4QrYAgxQ6oXZ9mpGRdflpF HTTP/1.1" 200 65
2021-02-26 09:38:34: Generated new state qxeEl0VzW526shK0qaDrvUDwQim44B.
2021-02-26 09:39:10: "GET /?state=qxeEl0VzW526shK0qaDrvUDwQim44B&code=4/0AY0e-g7cc7kjmLiYwbjkHb66wAYbntbJ4D8WOWbo0YVHrz15-symC5x0y8kFPmMmMpcdrA&scope=https://www.googleapis.com/auth/drive.file HTTP/1.1" 200 65
2021-02-26 09:39:10: Encoding `client_id` "659485896238-kno5ddp87h1i9gchhe1me1ocmdcior00.apps.googleusercontent.com" with `client_secret` as Basic auth credentials.
2021-02-26 09:39:10: Requesting url https://oauth2.googleapis.com/token using method POST.
2021-02-26 09:39:10: Supplying headers {'Accept': 'application/json', 'Content-Type': 'application/x-www-form-urlencoded;charset=UTF-8'} and data {'grant_type': 'authorization_code', 'code': '4/0AY0e-g7cc7kjmLiYwbjkHb66wAYbntbJ4D8WOWbo0YVHrz15-symC5x0y8kFPmMmMpcdrA', 'redirect_uri': 'http://localhost:57375/'}
2021-02-26 09:39:10: Passing through key word arguments {'timeout': None, 'auth': <requests.auth.HTTPBasicAuth object at 0x7fa435249460>, 'verify': True, 'proxies': None}.
2021-02-26 09:39:10: Starting new HTTPS connection (1): oauth2.googleapis.com:443
2021-02-26 09:39:10: https://oauth2.googleapis.com:443 "POST /token HTTP/1.1" 200 None
2021-02-26 09:39:10: Request to fetch token completed with status 200.
2021-02-26 09:39:10: Request url was https://oauth2.googleapis.com/token
2021-02-26 09:39:10: Request headers were {'User-Agent': 'python-requests/2.25.0', 'Accept-Encoding': 'gzip, deflate', 'Accept': 'application/json', 'Connection': 'keep-alive', 'Content-Type': 'application/x-www-form-urlencoded;charset=UTF-8', 'Content-Length': '157', 'Authorization': 'Basic NjU5NDg1ODk2MjM4LWtubzVkZHA4N2gxaTlnY2hoZTFtZTFvY21kY2lvcjAwLmFwcHMuZ29vZ2xldXNlcmNvbnRlbnQuY29tOlBRd2JiNlpyVlJLMVJVTTdfR21naXItRg=='}
2021-02-26 09:39:10: Request body was grant_type=authorization_code&code=4%2F0AY0e-g7cc7kjmLiYwbjkHb66wAYbntbJ4D8WOWbo0YVHrz15-symC5x0y8kFPmMmMpcdrA&redirect_uri=http%3A%2F%2Flocalhost%3A57375%2F
2021-02-26 09:39:10: Response headers were {'Date': 'Fri, 26 Feb 2021 08:39:10 GMT', 'Cache-Control': 'no-cache, no-store, max-age=0, must-revalidate', 'Pragma': 'no-cache', 'Expires': 'Mon, 01 Jan 1990 00:00:00 GMT', 'Content-Type': 'application/json; charset=utf-8', 'Vary': 'Origin, X-Origin, Referer', 'Content-Encoding': 'gzip', 'Server': 'scaffolding on HTTPServer2', 'X-XSS-Protection': '0', 'X-Frame-Options': 'SAMEORIGIN', 'X-Content-Type-Options': 'nosniff', 'Alt-Svc': 'h3-29=":443"; ma=2592000,h3-T051=":443"; ma=2592000,h3-Q050=":443"; ma=2592000,h3-Q046=":443"; ma=2592000,h3-Q043=":443"; ma=2592000,quic=":443"; ma=2592000; v="46,43"', 'Transfer-Encoding': 'chunked'} and content {
  "access_token": "ya29.A0AfH6SMDFbJbPfvjFFvqckVTdKB9ferYfoCnz8rkvX6VYEIa2OM-_3-c_tzniur0t4a3Nbv09JTLOFMh-ErwslFeCtZP7RrXdFoJHnn8rFa5_0KJQ8iY-3Y02BPHpLv4iijHHy9u6hCtK1lG6VX2-2ivdiWCa",
  "expires_in": 3599,
  "refresh_token": "1//09Eo9Zc27_tCHCgYIARAAGAkSNwF-L9IrhRrvXDsBIO856AqIKr6g06KF3cm5FXZmH1GJ98VP-nvrHBzbD7VT6ZQC2d0J8xWGhhU",
  "scope": "https://www.googleapis.com/auth/drive.file",
  "token_type": "Bearer"
}.
2021-02-26 09:39:10: Invoking 0 token response hooks.
2021-02-26 09:39:10: Obtained token {'access_token': 'ya29.A0AfH6SMDFbJbPfvjFFvqckVTdKB9ferYfoCnz8rkvX6VYEIa2OM-_3-c_tzniur0t4a3Nbv09JTLOFMh-ErwslFeCtZP7RrXdFoJHnn8rFa5_0KJQ8iY-3Y02BPHpLv4iijHHy9u6hCtK1lG6VX2-2ivdiWCa', 'expires_in': 3599, 'refresh_token': '1//09Eo9Zc27_tCHCgYIARAAGAkSNwF-L9IrhRrvXDsBIO856AqIKr6g06KF3cm5FXZmH1GJ98VP-nvrHBzbD7VT6ZQC2d0J8xWGhhU', 'scope': ['https://www.googleapis.com/auth/drive.file'], 'token_type': 'Bearer', 'expires_at': 1614332349.9356031}.
2021-02-26 09:39:10: file_cache is unavailable when using oauth2client >= 4.0.0 or google-auth
Traceback (most recent call last):
  File "/home/dmytro/pycharm/bouncer/bouncerenv/lib/python3.8/site-packages/googleapiclient/discovery_cache/file_cache.py", line 33, in <module>
    from oauth2client.contrib.locked_file import LockedFile
  File "/snap/pycharm-community/226/plugins/python-ce/helpers/pydev/_pydev_bundle/pydev_import_hook.py", line 21, in do_import
    module = self._system_import(name, *args, **kwargs)
ModuleNotFoundError: No module named 'oauth2client.contrib.locked_file'

During handling of the above exception, another exception occurred:

Traceback (most recent call last):
  File "/home/dmytro/pycharm/bouncer/bouncerenv/lib/python3.8/site-packages/googleapiclient/discovery_cache/file_cache.py", line 37, in <module>
    from oauth2client.locked_file import LockedFile
  File "/snap/pycharm-community/226/plugins/python-ce/helpers/pydev/_pydev_bundle/pydev_import_hook.py", line 21, in do_import
    module = self._system_import(name, *args, **kwargs)
ModuleNotFoundError: No module named 'oauth2client.locked_file'

During handling of the above exception, another exception occurred:

Traceback (most recent call last):
  File "/home/dmytro/pycharm/bouncer/bouncerenv/lib/python3.8/site-packages/googleapiclient/discovery_cache/__init__.py", line 44, in autodetect
    from . import file_cache
  File "/snap/pycharm-community/226/plugins/python-ce/helpers/pydev/_pydev_bundle/pydev_import_hook.py", line 21, in do_import
    module = self._system_import(name, *args, **kwargs)
  File "/home/dmytro/pycharm/bouncer/bouncerenv/lib/python3.8/site-packages/googleapiclient/discovery_cache/file_cache.py", line 40, in <module>
    raise ImportError(
ImportError: file_cache is unavailable when using oauth2client >= 4.0.0 or google-auth
2021-02-26 09:39:11: URL being requested: GET https://www.googleapis.com/discovery/v1/apis/drive/v3/rest
2021-02-26 09:39:30: Starting new HTTPS connection (1): api.telegram.org:443
2021-02-26 09:39:30: https://api.telegram.org:443 "GET /bot1465974332:AAGqzVPLOfgUzKK3ZtEb9U9k8wb9srVk_LE/getUpdates?offset=0 HTTP/1.1" 200 23
2021-02-26 09:39:33: Starting new HTTPS connection (1): api.telegram.org:443
2021-02-26 09:39:33: https://api.telegram.org:443 "GET /bot1465974332:AAGqzVPLOfgUzKK3ZtEb9U9k8wb9srVk_LE/getUpdates?offset=0 HTTP/1.1" 200 23
2021-02-26 09:39:36: Starting new HTTPS connection (1): api.telegram.org:443
2021-02-26 09:39:36: https://api.telegram.org:443 "GET /bot1465974332:AAGqzVPLOfgUzKK3ZtEb9U9k8wb9srVk_LE/getUpdates?offset=0 HTTP/1.1" 200 23
2021-02-26 09:39:39: Starting new HTTPS connection (1): api.telegram.org:443
2021-02-26 09:39:39: https://api.telegram.org:443 "GET /bot1465974332:AAGqzVPLOfgUzKK3ZtEb9U9k8wb9srVk_LE/getUpdates?offset=0 HTTP/1.1" 200 23
2021-02-26 09:39:42: Starting new HTTPS connection (1): api.telegram.org:443
2021-02-26 09:39:42: https://api.telegram.org:443 "GET /bot1465974332:AAGqzVPLOfgUzKK3ZtEb9U9k8wb9srVk_LE/getUpdates?offset=0 HTTP/1.1" 200 23
2021-02-26 09:39:45: Starting new HTTPS connection (1): api.telegram.org:443
2021-02-26 09:39:46: https://api.telegram.org:443 "GET /bot1465974332:AAGqzVPLOfgUzKK3ZtEb9U9k8wb9srVk_LE/getUpdates?offset=0 HTTP/1.1" 200 23
2021-02-26 09:39:49: Starting new HTTPS connection (1): api.telegram.org:443
2021-02-26 09:39:49: https://api.telegram.org:443 "GET /bot1465974332:AAGqzVPLOfgUzKK3ZtEb9U9k8wb9srVk_LE/getUpdates?offset=0 HTTP/1.1" 200 23
2021-02-26 09:40:53: Starting new HTTPS connection (1): api.telegram.org:443
2021-02-26 09:40:53: https://api.telegram.org:443 "GET /bot1465974332:AAGqzVPLOfgUzKK3ZtEb9U9k8wb9srVk_LE/getMe HTTP/1.1" 200 206
2021-02-26 09:40:53: file_cache is unavailable when using oauth2client >= 4.0.0 or google-auth
Traceback (most recent call last):
  File "/home/dmytro/pycharm/bouncer/bouncerenv/lib/python3.8/site-packages/googleapiclient/discovery_cache/file_cache.py", line 33, in <module>
    from oauth2client.contrib.locked_file import LockedFile
  File "/snap/pycharm-community/226/plugins/python-ce/helpers/pydev/_pydev_bundle/pydev_import_hook.py", line 21, in do_import
    module = self._system_import(name, *args, **kwargs)
ModuleNotFoundError: No module named 'oauth2client.contrib.locked_file'

During handling of the above exception, another exception occurred:

Traceback (most recent call last):
  File "/home/dmytro/pycharm/bouncer/bouncerenv/lib/python3.8/site-packages/googleapiclient/discovery_cache/file_cache.py", line 37, in <module>
    from oauth2client.locked_file import LockedFile
  File "/snap/pycharm-community/226/plugins/python-ce/helpers/pydev/_pydev_bundle/pydev_import_hook.py", line 21, in do_import
    module = self._system_import(name, *args, **kwargs)
ModuleNotFoundError: No module named 'oauth2client.locked_file'

During handling of the above exception, another exception occurred:

Traceback (most recent call last):
  File "/home/dmytro/pycharm/bouncer/bouncerenv/lib/python3.8/site-packages/googleapiclient/discovery_cache/__init__.py", line 44, in autodetect
    from . import file_cache
  File "/snap/pycharm-community/226/plugins/python-ce/helpers/pydev/_pydev_bundle/pydev_import_hook.py", line 21, in do_import
    module = self._system_import(name, *args, **kwargs)
  File "/home/dmytro/pycharm/bouncer/bouncerenv/lib/python3.8/site-packages/googleapiclient/discovery_cache/file_cache.py", line 40, in <module>
    raise ImportError(
ImportError: file_cache is unavailable when using oauth2client >= 4.0.0 or google-auth
2021-02-26 09:40:53: URL being requested: GET https://www.googleapis.com/discovery/v1/apis/drive/v3/rest
2021-02-26 09:41:04: file_cache is unavailable when using oauth2client >= 4.0.0 or google-auth
Traceback (most recent call last):
  File "/home/dmytro/pycharm/bouncer/bouncerenv/lib/python3.8/site-packages/googleapiclient/discovery_cache/file_cache.py", line 33, in <module>
    from oauth2client.contrib.locked_file import LockedFile
  File "/snap/pycharm-community/226/plugins/python-ce/helpers/pydev/_pydev_bundle/pydev_import_hook.py", line 21, in do_import
    module = self._system_import(name, *args, **kwargs)
ModuleNotFoundError: No module named 'oauth2client.contrib.locked_file'

During handling of the above exception, another exception occurred:

Traceback (most recent call last):
  File "/home/dmytro/pycharm/bouncer/bouncerenv/lib/python3.8/site-packages/googleapiclient/discovery_cache/file_cache.py", line 37, in <module>
    from oauth2client.locked_file import LockedFile
  File "/snap/pycharm-community/226/plugins/python-ce/helpers/pydev/_pydev_bundle/pydev_import_hook.py", line 21, in do_import
    module = self._system_import(name, *args, **kwargs)
ModuleNotFoundError: No module named 'oauth2client.locked_file'

During handling of the above exception, another exception occurred:

Traceback (most recent call last):
  File "/home/dmytro/pycharm/bouncer/bouncerenv/lib/python3.8/site-packages/googleapiclient/discovery_cache/__init__.py", line 44, in autodetect
    from . import file_cache
  File "/snap/pycharm-community/226/plugins/python-ce/helpers/pydev/_pydev_bundle/pydev_import_hook.py", line 21, in do_import
    module = self._system_import(name, *args, **kwargs)
  File "/home/dmytro/pycharm/bouncer/bouncerenv/lib/python3.8/site-packages/googleapiclient/discovery_cache/file_cache.py", line 40, in <module>
    raise ImportError(
ImportError: file_cache is unavailable when using oauth2client >= 4.0.0 or google-auth
2021-02-26 09:41:04: URL being requested: GET https://www.googleapis.com/discovery/v1/apis/drive/v3/rest
2021-02-26 09:41:39: Starting new HTTPS connection (1): api.telegram.org:443
2021-02-26 09:41:40: https://api.telegram.org:443 "GET /bot1465974332:AAGqzVPLOfgUzKK3ZtEb9U9k8wb9srVk_LE/getMe HTTP/1.1" 200 206
2021-02-26 09:41:51: Starting new HTTPS connection (1): api.telegram.org:443
2021-02-26 09:41:51: https://api.telegram.org:443 "GET /bot1465974332:AAGqzVPLOfgUzKK3ZtEb9U9k8wb9srVk_LE/getUpdates?offset=0 HTTP/1.1" 200 23
